Workbook
Name AAPL1: 'Expected Return'!$B$3:$B$63
Name AMZN1: 'Expected Return'!$C$3:$C$63
Name AVGO1: 'Expected Return'!$D$3:$D$63
Name GOOGL1: 'Expected Return'!$E$3:$E$63
Name Mastercard: 'Expected Return'!$F$3:$F$63
Name Means: 'Efficient portfolio frontier'!$Q$16:$Q$25
Name Meta1: 'Expected Return'!$G$3:$G$63
Name MSFT1: 'Expected Return'!$H$3:$H$63
Name NVDA1: 'Expected Return'!$I$3:$I$63
Name ORCL1: 'Expected Return'!$J$3:$J$63
Name TSLA1: 'Expected Return'!$K$3:$K$63
Name varcov: 'Efficient portfolio frontier'!$E$16:$N$25
Name Weeights: 'Efficient portfolio frontier'!#REF!
Name Weights: 'Efficient portfolio frontier'!$T$16:$AC$16

Sheet Historical Data
A2: Date | B2: AAPL | C2: AMZN | D2: AVGO | E2: GOOGL | F2: MA | G2: META | H2: MSFT | I2: NVDA | J2: ORCL | K2: TSLA
A3: 44075 | B3: 112.6504 | C3: 157.4365 | D3: 32.26561 | E3: 72.77804 | F3: 328.3466 | G3: 260.2954 | H3: 201.6698 | I3: 13.48529 | J3: 55.46035 | K3: 143.0033
A4: 44105 | B4: 105.8901 | C4: 151.8075 | D4: 31.24691 | E4: 80.252 | F4: 280.2554 | G4: 261.4979 | H4: 194.1334 | I4: 12.49585 | J4: 52.12528 | K4: 129.3467
A5: 44136 | B5: 115.8021 | C5: 158.402 | D5: 35.88975 | E5: 87.11913 | F5: 327.1154 | G5: 275.273 | H5: 205.2557 | I5: 13.36072 | J5: 53.83809 | K5: 189.2
A6: 44166 | B6: 129.2926 | C6: 162.8465 | D6: 39.13125 | E6: 87.03175 | F6: 346.975 | G6: 271.4864 | H6: 213.8203 | I6: 13.01527 | J6: 60.33931 | K6: 235.2233
A7: 44197 | B7: 128.5813 | C7: 160.31 | D7: 40.60487 | E7: 90.74214 | F7: 307.4598 | G7: 256.7473 | H7: 222.9914 | I7: 12.95404 | J7: 56.36582 | K7: 264.51
A8: 44228 | B8: 118.1553 | C8: 154.6465 | D8: 42.35073 | E8: 100.403 | F8: 344.4073 | G8: 256.0416 | H8: 223.3952 | I8: 13.6768 | J8: 60.40167 | K8: 225.1667
A9: 44256 | B9: 119.2003 | C9: 154.704 | D9: 41.79101 | E9: 102.4196 | F9: 346.5485 | G9: 292.7254 | H9: 227.1762 | I9: 13.31156 | J9: 65.70121 | K9: 222.6433
A10: 44287 | B10: 128.2855 | C10: 173.371 | D10: 41.44003 | E10: 116.8689 | F10: 371.8645 | G10: 323.0882 | H10: 242.988 | I10: 14.97341 | J10: 70.96332 | K10: 236.48
A11: 44317 | B11: 121.6009 | C11: 161.1535 | D11: 42.90524 | E11: 117.0353 | F11: 351.3743 | G11: 326.7159 | H11: 240.5791 | I11: 16.20544 | J11: 74.04443 | K11: 208.4067
A12: 44348 | B12: 133.8797 | C12: 172.008 | D12: 43.31491 | E12: 121.2532 | F12: 355.7691 | G12: 345.5796 | H12: 261.6283 | I12: 19.9544 | J12: 73.19808 | K12: 226.5667
A13: 44378 | B13: 142.5795 | C13: 166.3795 | D13: 44.43763 | E13: 133.8036 | F13: 376.0868 | G13: 354.1169 | H13: 275.1589 | I13: 19.45657 | J13: 81.94348 | K13: 229.0667
A14: 44409 | B14: 148.4153 | C14: 173.5395 | D14: 45.51881 | E14: 143.7063 | F14: 337.7882 | G14: 377.0555 | H14: 291.5481 | I14: 22.33629 | J14: 84.12399 | K14: 245.24
... A64: 45931 | B64: 247.45 | C64: 214.47 | D64: 354.15 | E64: 251.46 | F64: 549.88 | G64: 712.07 | H64: 511.61 | I64: 181.81 | J64: 313 | K64: 428.75

Sheet Expected Return
B1: EXPECTED RETURNS
A2: Date | B2: AAPL | C2: AMZN | D2: AVGO | E2: GOOGL | F2: MA | G2: META | H2: MSFT | I2: NVDA | J2: ORCL | K2: TSLA
A3: 44075 | B3: =LN('Historical Data'!B4/'Historical Data'!B3) -> -0.061887454 | C3: =LN('Historical Data'!C4/'Historical Data'!C3) -> -0.036408932 | D3: =LN('Historical Data'!D4/'Historical Data'!D3) -> -0.032081466 | E3: =LN('Historical Data'!E4/'Historical Data'!E3) -> 0.097757422 | F3: =LN('Historical Data'!F4/'Historical Data'!F3) -> -0.15836843 | G3: =LN('Historical Data'!G4/'Historical Data'!G3) -> 0.004609113 | H3: =LN('Historical Data'!H4/'Historical Data'!H3) -> -0.038086155 | I3: =LN('Historical Data'!I4/'Historical Data'!I3) -> -0.076202873 | ... K3: =LN('Historical Data'!K4/'Historical Data'!K3) -> -0.10037131 | N3: =J3*12 -> -0.74421959
A4: 44105 | B4: =LN('Historical Data'!B5/'Historical Data'!B4) -> 0.089480936 | C4: =LN('Historical Data'!C5/'Historical Data'!C4) -> 0.042522835 | D4: =LN('Historical Data'!D5/'Historical Data'!D4) -> 0.13853125 | E4: =LN('Historical Data'!E5/'Historical Data'!E4) -> 0.082104809 | F4: =LN('Historical Data'!F5/'Historical Data'!F4) -> 0.15461168 | G4: =LN('Historical Data'!G5/'Historical Data'!G4) -> 0.05133708 | H4: =LN('Historical Data'!H5/'Historical Data'!H4) -> 0.055710967 | I4: =LN('Historical Data'!I5/'Historical Data'!I4) -> 0.06692247 | ... K4: =LN('Historical Data'!K5/'Historical Data'!K4) -> 0.38030826
A5: 44136 | B5: =LN('Historical Data'!B6/'Historical Data'!B5) -> 0.11019535 | C5: =LN('Historical Data'!C6/'Historical Data'!C5) -> 0.027671934 | D5: =LN('Historical Data'!D6/'Historical Data'!D5) -> 0.086469641 | E5: =LN('Historical Data'!E6/'Historical Data'!E5) -> -0.0010034977 | F5: =LN('Historical Data'!F6/'Historical Data'!F5) -> 0.058939717 | G5: =LN('Historical Data'!G6/'Historical Data'!G5) -> -0.013851286 | H5: =LN('Historical Data'!H6/'Historical Data'!H5) -> 0.040879424 | I5: =LN('Historical Data'!I6/'Historical Data'!I5) -> -0.026195775 | ... K5: =LN('Historical Data'!K6/'Historical Data'!K5) -> 0.21773062
A6: 44166 | B6: =LN('Historical Data'!B7/'Historical Data'!B6) -> -0.0055166638 | C6: =LN('Historical Data'!C7/'Historical Data'!C6) -> -0.015698599 | D6: =LN('Historical Data'!D7/'Historical Data'!D6) -> 0.03696663 | E6: =LN('Historical Data'!E7/'Historical Data'!E6) -> 0.041748863 | F6: =LN('Historical Data'!F7/'Historical Data'!F6) -> -0.12090838 | G6: =LN('Historical Data'!G7/'Historical Data'!G6) -> -0.055819713 | H6: =LN('Historical Data'!H7/'Historical Data'!H6) -> 0.041997263 | I6: =LN('Historical Data'!I7/'Historical Data'!I6) -> -0.0047155749 | ... K6: =LN('Historical Data'!K7/'Historical Data'!K6) -> 0.11734378
A7: 44197 | B7: =LN('Historical Data'!B8/'Historical Data'!B7) -> -0.084561528 | C7: =LN('Historical Data'!C8/'Historical Data'!C7) -> -0.035967574 | D7: =LN('Historical Data'!D8/'Historical Data'!D7) -> 0.042097648 | E7: =LN('Historical Data'!E8/'Historical Data'!E7) -> 0.10117023 | F7: =LN('Historical Data'!F8/'Historical Data'!F7) -> 0.11348062 | G7: =LN('Historical Data'!G8/'Historical Data'!G7) -> -0.0027524014 | H7: =LN('Historical Data'!H8/'Historical Data'!H7) -> 0.0018091946 | I7: =LN('Historical Data'!I8/'Historical Data'!I7) -> 0.054293258 | ... K7: =LN('Historical Data'!K8/'Historical Data'!K7) -> -0.16103804
A8: 44228 | B8: =LN('Historical Data'!B9/'Historical Data'!B8) -> 0.0088054105 | C8: =LN('Historical Data'!C9/'Historical Data'!C8) -> 0.00037174662 | D8: =LN('Historical Data'!D9/'Historical Data'!D8) -> -0.013304414 | E8: =LN('Historical Data'!E9/'Historical Data'!E8) -> 0.019886013 | F8: =LN('Historical Data'!F9/'Historical Data'!F8) -> 0.0061978114 | G8: =LN('Historical Data'!G9/'Historical Data'!G8) -> 0.13389504 | H8: =LN('Historical Data'!H9/'Historical Data'!H8) -> 0.016783528 | I8: =LN('Historical Data'!I9/'Historical Data'!I8) -> -0.027068136 | ... K8: =LN('Historical Data'!K9/'Historical Data'!K8) -> -0.011270078
A9: 44256 | B9: =LN('Historical Data'!B10/'Historical Data'!B9) -> 0.073452977 | C9: =LN('Historical Data'!C10/'Historical Data'!C9) -> 0.11392019 | D9: =LN('Historical Data'!D10/'Historical Data'!D9) -> -0.0084339227 | E9: =LN('Historical Data'!E10/'Historical Data'!E9) -> 0.13197469 | F9: =LN('Historical Data'!F10/'Historical Data'!F9) -> 0.070506761 | G9: =LN('Historical Data'!G10/'Historical Data'!G9) -> 0.098690383 | H9: =LN('Historical Data'!H10/'Historical Data'!H9) -> 0.067286132 | I9: =LN('Historical Data'!I10/'Historical Data'!I9) -> 0.11764313 | ... K9: =LN('Historical Data'!K10/'Historical Data'!K9) -> 0.060292699
A10: 44287 | B10: =LN('Historical Data'!B11/'Historical Data'!B10) -> -0.053513878 | C10: =LN('Historical Data'!C11/'Historical Data'!C10) -> -0.07307648 | D10: =LN('Historical Data'!D11/'Historical Data'!D10) -> 0.034746641 | E10: =LN('Historical Data'!E11/'Historical Data'!E10) -> 0.001422805 | F10: =LN('Historical Data'!F11/'Historical Data'!F10) -> -0.056677504 | G10: =LN('Historical Data'!G11/'Historical Data'!G10) -> 0.011165635 | H10: =LN('Historical Data'!H11/'Historical Data'!H10) -> -0.0099631258 | I10: =LN('Historical Data'!I11/'Historical Data'!I10) -> 0.079071027 | ... K10: =LN('Historical Data'!K11/'Historical Data'!K10) -> -0.12637218
A11: 44317 | B11: =LN('Historical Data'!B12/'Historical Data'!B11) -> 0.096197265 | C11: =LN('Historical Data'!C12/'Historical Data'!C11) -> 0.06518366 | D11: =LN('Historical Data'!D12/'Historical Data'!D11) -> 0.0095029545 | E11: =LN('Historical Data'!E12/'Historical Data'!E11) -> 0.035405323 | F11: =LN('Historical Data'!F12/'Historical Data'!F11) -> 0.012429888 | G11: =LN('Historical Data'!G12/'Historical Data'!G11) -> 0.056132021 | H11: =LN('Historical Data'!H12/'Historical Data'!H11) -> 0.083875861 | I11: =LN('Historical Data'!I12/'Historical Data'!I11) -> 0.20810268 | ... K11: =LN('Historical Data'!K12/'Historical Data'!K11) -> 0.083547924
A12: 44348 | B12: =LN('Historical Data'!B13/'Historical Data'!B12) -> 0.062958103 | C12: =LN('Historical Data'!C13/'Historical Data'!C12) -> -0.033269664 | D12: =LN('Historical Data'!D13/'Historical Data'!D12) -> 0.025589715 | E12: =LN('Historical Data'!E13/'Historical Data'!E12) -> 0.098492132 | F12: =LN('Historical Data'!F13/'Historical Data'!F12) -> 0.055538043 | G12: =LN('Historical Data'!G13/'Historical Data'!G12) -> 0.024404077 | H12: =LN('Historical Data'!H13/'Historical Data'!H12) -> 0.050423955 | I12: =LN('Historical Data'!I13/'Historical Data'!I12) -> -0.025264868 | ... K12: =LN('Historical Data'!K13/'Historical Data'!K12) -> 0.010973845
A13: 44378 | B13: =LN('Historical Data'!B14/'Historical Data'!B13) -> 0.040114686 | C13: =LN('Historical Data'!C14/'Historical Data'!C13) -> 0.042133915 | D13: =LN('Historical Data'!D14/'Historical Data'!D13) -> 0.024039014 | E13: =LN('Historical Data'!E14/'Historical Data'!E13) -> 0.07139858 | F13: =LN('Historical Data'!F14/'Historical Data'!F13) -> -0.1074009 | G13: =LN('Historical Data'!G14/'Historical Data'!G13) -> 0.062765307 | H13: =LN('Historical Data'!H14/'Historical Data'!H13) -> 0.057856252 | I13: =LN('Historical Data'!I14/'Historical Data'!I13) -> 0.13802791 | ... K13: =LN('Historical Data'!K14/'Historical Data'!K13) -> 0.068224095
A14: 44409 | B14: =LN('Historical Data'!B15/'Historical Data'!B14) -> -0.068965054 | C14: =LN('Historical Data'!C15/'Historical Data'!C14) -> -0.055003405 | D14: =LN('Historical Data'!D15/'Historical Data'!D14) -> -0.025007807 | E14: =LN('Historical Data'!E15/'Historical Data'!E14) -> -0.079226387 | F14: =LN('Historical Data'!F15/'Historical Data'!F14) -> 0.0041790867 | G14: =LN('Historical Data'!G15/'Historical Data'!G14) -> -0.11138822 | H14: =LN('Historical Data'!H15/'Historical Data'!H14) -> -0.066493568 | I14: =LN('Historical Data'!I15/'Historical Data'!I14) -> -0.077308267 | ... K14: =LN('Historical Data'!K15/'Historical Data'!K14) -> 0.052632452
A15: 44440 | B15: =LN('Historical Data'!B16/'Historical Data'!B15) -> 0.05700147 | C15: =LN('Historical Data'!C16/'Historical Data'!C15) -> 0.026254724 | D15: =LN('Historical Data'!D16/'Historical Data'!D15) -> 0.09932043 | E15: =LN('Historical Data'!E16/'Historical Data'!E15) -> 0.10210432 | F15: =LN('Historical Data'!F16/'Historical Data'!F15) -> -0.035601216 | G15: =LN('Historical Data'!G16/'Historical Data'!G15) -> -0.047734188 | H15: =LN('Historical Data'!H16/'Historical Data'!H15) -> 0.16236607 | I15: =LN('Historical Data'!I16/'Historical Data'!I15) -> 0.21039578 | ... K15: =LN('Historical Data'!K16/'Historical Data'!K15) -> 0.36223027
... A63: 45901 | B63: =LN('Historical Data'!B64/'Historical Data'!B63) -> -0.02860297 | C63: =LN('Historical Data'!C64/'Historical Data'!C63) -> -0.02350122 | D63: =LN('Historical Data'!D64/'Historical Data'!D63) -> 0.072612593 | E63: =LN('Historical Data'!E64/'Historical Data'!E63) -> 0.034704909 | F63: =LN('Historical Data'!F64/'Historical Data'!F63) -> -0.03252715 | G63: =LN('Historical Data'!G64/'Historical Data'!G63) -> -0.030175711 | H63: =LN('Historical Data'!H64/'Historical Data'!H63) -> -0.012316096 | I63: =LN('Historical Data'!I64/'Historical Data'!I63) -> -0.025841638 | ... K63: =LN('Historical Data'!K64/'Historical Data'!K63) -> -0.036570872
A64: Monthly MEAN RETURN | B64: =AVERAGE(B3:B63) -> 0.012900317 | C64: =AVERAGE(C3:C63) -> 0.0050679945 | D64: =AVERAGE(D3:D63) -> 0.039274075 | E64: =AVERAGE(E3:E63) -> 0.020325732 | F64: =AVERAGE(F3:F63) -> 0.008452956 | G64: =AVERAGE(G3:G63) -> 0.01649769 | H64: =AVERAGE(H3:H63) -> 0.015261162 | I64: =AVERAGE(I3:I63) -> 0.042645291 | ... K64: =AVERAGE(K3:K63) -> 0.018000103 | L64: =AVERAGE(B64:K64) -> 0.020679474
A65: annual MEAN RETURN | B65: =B64*12 -> 0.1548038 | C65: =C64*12 -> 0.060815934 | D65: =D64*12 -> 0.4712889 | E65: =E64*12 -> 0.24390879 | F65: =F64*12 -> 0.10143547 | G65: =G64*12 -> 0.19797228 | H65: =H64*12 -> 0.18313395 | I65: =I64*12 -> 0.51174349 | ... K65: =K64*12 -> 0.21600124 | L65: =AVERAGE(B65:K65) -> 0.24815369
A66: Variance | B66: =_xlfn.VAR.S(AAPL1) -> 0.0050962477 | C66: =_xlfn.VAR.S(C3:C64) -> 0.0074741095 | D66: =_xlfn.VAR.S(D3:D64) -> 0.0096221283 | E66: =_xlfn.VAR.S(E3:E64) -> 0.0060091084 | F66: =_xlfn.VAR.S(F3:F64) -> 0.0046605782 | G66: =_xlfn.VAR.S(G3:G64) -> 0.014162001 | H66: =_xlfn.VAR.S(H3:H64) -> 0.0038336689 | I66: =_xlfn.VAR.S(I3:I64) -> 0.019596192 | J66: =_xlfn.VAR.S(J3:J64) -> 0.009793327 | K66: =_xlfn.VAR.S(K3:K64) -> 0.030555444 | L66: =AVERAGE(B66:K66) -> 0.01108028
A67: annual VAR | B67: =B66*12 -> 0.061154972 | C67: =C66*12 -> 0.089689313 | D67: =D66*12 -> 0.11546554 | E67: =E66*12 -> 0.072109301 | F67: =F66*12 -> 0.055926939 | G67: =G66*12 -> 0.16994401 | H67: =H66*12 -> 0.046004026 | I67: =I66*12 -> 0.2351543 | ... K67: =K66*12 -> 0.36666533 | L67: =AVERAGE(B67:K67) -> 0.13296337
A68: standard Dev annual | B68: =SQRT(B67) -> 0.24729531 | C68: =SQRT(C67) -> 0.29948174 | D68: =SQRT(D67) -> 0.33980221 | E68: =SQRT(E67) -> 0.26853175 | F68: =SQRT(F67) -> 0.23648877 | G68: =SQRT(G67) -> 0.41224266 | H68: =SQRT(H67) -> 0.21448549 | I68: =SQRT(I67) -> 0.48492711 | ... K68: =SQRT(K67) -> 0.60552897 | L68: =AVERAGE(B68:K68) -> 0.34515958
L69: Total

Sheet Standart Deviation
A1: Standart Deviation
A2: AAPL | B2: AMZN | C2: AVGO | D2: GOOGL | E2: MA | F2: META | G2: MSFT | H2: NVDA | I2: ORCL | J2: TSLA
A3: ='Expected Return'!B68 -> 0.24729531 | B3: ='Expected Return'!C68 -> 0.29948174 | C3: ='Expected Return'!D68 -> 0.33980221 | D3: ='Expected Return'!E68 -> 0.26853175 | E3: ='Expected Return'!F68 -> 0.23648877 | F3: ='Expected Return'!G68 -> 0.41224266 | G3: ='Expected Return'!H68 -> 0.21448549 | H3: ='Expected Return'!I68 -> 0.48492711 | ... J3: ='Expected Return'!K68 -> 0.60552897

Sheet Ratios
B1: GMVP | C1: Effective PF | D1: Mutual fund SEEGX | E1: Russell 1000 | F1: MSCI World index
A2: Sharpe ratio | B2: =('Efficient portfolio frontier'!AD20-Ratios!J2)/'Efficient portfolio frontier'!AF20 -> 0.68427689 | C2: =('Efficient portfolio frontier'!AD34-Ratios!J2)/'Efficient portfolio frontier'!AF34 -> 1.2717541 | D2: 1.45 | E2: 0.88 | F2: 1.05 | I2: Rf = | J2: 0.04
A3: Beta | B3: =1.02*'Efficient portfolio frontier'!Z20+'Efficient portfolio frontier'!X20*1.03+'Efficient portfolio frontier'!W20*0.99+'Efficient portfolio frontier'!T20*1.09 -> 1.0276957 | C3: ='Efficient portfolio frontier'!AB34*1.53+'Efficient portfolio frontier'!AA34*1.77+'Efficient portfolio frontier'!X34*1.03+'Efficient portfolio frontier'!W34*0.99+'Efficient portfolio frontier'!V34*1.21+'Efficient portfolio frontier'!T34*1.09 -> 1.2369563 | D3: 0.98 | E3: 1.18 | F3: 1 | I3: US Bonds
A4: Jensen's alpha | B4: ='Efficient portfolio frontier'!AF20-(Ratios!J2+Ratios!B3*(J5-Ratios!J2)) -> 0.020888961 | C4: ='Efficient portfolio frontier'!AD34-(Ratios!J2+Ratios!C3*(Ratios!J5-Ratios!J2)) -> 0.18514103 | D4: 0.0302 | E4: -0.0133 | F4: 0.0017
A5: Treynor ratio | B5: =('Efficient portfolio frontier'!AD20-Ratios!J2)/Ratios!B3 -> 0.11581253 | C5: =('Efficient portfolio frontier'!AD34-Ratios!J2)/Ratios!C3 -> 0.25967467 | D5: 10.96 | E5: 12.58 | F5: 11.92 | I5: Rm = | J5: 0.15
A6: Standard deviation | B6: ='Efficient portfolio frontier'!AF20 -> 0.17393548 | C6: ='Efficient portfolio frontier'!AF34 -> 0.25256944 | D6: 0.1593 | E6: 0.1883 | F6: 0.1146 | I6: MSCI World index

Sheet Fact Sheet 1
A1: Holdings | B1: Colonne1 | C1: Colonne2 | D1: Colonne3 | E1: Colonne4 | F1: Colonne5 | G1: Colonne6
A2: Top 10 (%) | S2: Holdings | T2: Colonne1 | U2: Colonne2
A3: AVGO | C3: 0.47501974 | K3: GMVP | L3: Effective PF | M3: Mutual fund SEEGX | N3: Russell 1000 | O3: MSCI World index | S3: Top 10 (%)
A4: ORCL | C4: 0.19808035 | J4: Sharpe ratio | K4: 0.68427689 | L4: 1.2717541 | M4: 1.45 | N4: 0.88 | O4: 1.05 | S4: AVGO | U4: 0.47501974
A5: GOOGL | C5: 0.14450369 | J5: Beta | K5: 1.0276957 | L5: 1.2369563 | M5: 0.98 | N5: 1.18 | O5: 1 | S5: ORCL | U5: 0.19808035
A6: MA | C6: 0.12041574 | J6: Jensen's alpha | K6: 0.020888961 | L6: 0.18514103 | M6: 0.0302 | N6: -0.0133 | O6: 0.0017 | S6: GOOGL | U6: 0.14450369
A7: NVDA | C7: 0.035991037 | J7: Treynor ratio | K7: 0.11581253 | L7: 0.25967467 | M7: 10.96 | N7: 12.58 | O7: 11.92 | S7: MA | U7: 0.12041574
A8: AAPL | C8: 0.025989442 | S8: NVDA | U8: 0.035991037
A9: AMZN | C9: 0 | S9: AAPL | U9: 0.025989442
A10: META | C10: 0 | S10: AMZN | U10: 0
A11: MSFT | C11: 0 | J11: #VALUE! | S11: META | U11: 0
A12: TSLA | C12: 0 | S12: MSFT | U12: 0
S13: TSLA | U13: 0
L16: #VALUE!
E18: Colonne1
L20: #VALUE!
L21: #VALUE!
L22: #VALUE!
L23: #VALUE!
S24: Sector | T24: Constituents | U24: Weight (%)
S25: Information Technology | T25: AVGO (47.5%) + ORCL (19.8%) + NVDA (3.6%) + AAPL (2.6%) | U25: 73.5 %
S26: Communication Services | T26: GOOGL (14.5%) | U26: 14.5 %
S27: Financials | T27: MA (12.0%) | U27: 12.0 %
S28: Other Sectors | T28: AMZN, META, MSFT, TSLA (0%) | U28: 0

Sheet Fact Sheet 2
B1: EXPECTED RETURNS | N1: AVGO | O1: ORCL | P1: GOOGL | Q1: MA | R1: NVDA | S1: AAPL | T1: somme annual return | U1: Résultat avec 10000 avec notre portefeuille
A2: Date | B2: AAPL | C2: AMZN | D2: AVGO | E2: GOOGL | F2: MA | G2: META | H2: MSFT | I2: NVDA | J2: ORCL | K2: TSLA | M2: 2020 | N2: =(((1+AVERAGE(D3:D6))^12)-1)*$O13 -> 0.45380929 | O2: =(((1+AVERAGE(J3:J6))^12)-1)*19.81% -> 0.0098416799 | P2: =(((1+AVERAGE(E3:E6))^12)-1)*14.45% -> 0.13069952 | Q2: =(((1+AVERAGE(F3:F6))^12)-1)*12.04% -> -0.021707851 | R2: =(((1+AVERAGE(I3:I6))^12)-1)*3.6% -> -0.0041086815 | S2: =(((1+AVERAGE(B3:B6))^12)-1)*2.6% -> 0.012416737 | T2: =SUM(N2:S2) -> 0.58095069 | U2: =10000*(1+T2) -> 15809.507
A3: 44075 | B3: =LN('Historical Data'!B4/'Historical Data'!B3) -> -0.061887454 | C3: =LN('Historical Data'!C4/'Historical Data'!C3) -> -0.036408932 | D3: =LN('Historical Data'!D4/'Historical Data'!D3) -> -0.032081466 | E3: =LN('Historical Data'!E4/'Historical Data'!E3) -> 0.097757422 | F3: =LN('Historical Data'!F4/'Historical Data'!F3) -> -0.15836843 | G3: =LN('Historical Data'!G4/'Historical Data'!G3) -> 0.004609113 | H3: =LN('Historical Data'!H4/'Historical Data'!H3) -> -0.038086155 | I3: =LN('Historical Data'!I4/'Historical Data'!I3) -> -0.076202873 | ... K3: =LN('Historical Data'!K4/'Historical Data'!K3) -> -0.10037131 | M3: 2021 | N3: =(((1+AVERAGE(D7:D18))^12)-1)*47.5% -> 0.15886574 | O3: =(((1+AVERAGE(J7:J18))^12)-1)*19.81% -> 0.070993214 | P3: =(((1+AVERAGE(E7:E18))^12)-1)*14.45% -> 0.068143775 | Q3: =(((1+AVERAGE(F7:F18))^12)-1)*12.04% -> 0.027146385 | R3: =(((1+AVERAGE(I7:I18))^12)-1)*3.6% -> 0.030827295 | S3: =(((1+AVERAGE(B7:B18))^12)-1)*2.6% -> 0.0085320901 | T3: =SUM(N3:S3) -> 0.3645085 | U3: =U2*(1+T3) -> 21572.207
A4: 44105 | B4: =LN('Historical Data'!B5/'Historical Data'!B4) -> 0.089480936 | C4: =LN('Historical Data'!C5/'Historical Data'!C4) -> 0.042522835 | D4: =LN('Historical Data'!D5/'Historical Data'!D4) -> 0.13853125 | E4: =LN('Historical Data'!E5/'Historical Data'!E4) -> 0.082104809 | F4: =LN('Historical Data'!F5/'Historical Data'!F4) -> 0.15461168 | G4: =LN('Historical Data'!G5/'Historical Data'!G4) -> 0.05133708 | H4: =LN('Historical Data'!H5/'Historical Data'!H4) -> 0.055710967 | I4: =LN('Historical Data'!I5/'Historical Data'!I4) -> 0.06692247 | ... K4: =LN('Historical Data'!K5/'Historical Data'!K4) -> 0.38030826 | M4: 2022 | N4: =(((1+AVERAGE(E19:E30))^12)-1)*47.5% -> -0.12945777 | O4: =(((1+AVERAGE(J19:J30))^12)-1)*19.81% -> 0.021467473 | P4: =(((1+AVERAGE(E19:E30))^12)-1)*14.45% -> -0.039382418 | Q4: =(((1+AVERAGE(F19:F30))^12)-1)*12.04% -> -0.0042468574 | R4: =(((1+AVERAGE(I19:I30))^12)-1)*3.6% -> -0.007310566 | S4: =(((1+AVERAGE(B19:B30))^12)-1)*2.6% -> -0.0044424702 | T4: =SUM(N4:S4) -> -0.16337261 | U4: =U3*(1+T4) -> 18047.899
A5: 44136 | B5: =LN('Historical Data'!B6/'Historical Data'!B5) -> 0.11019535 | C5: =LN('Historical Data'!C6/'Historical Data'!C5) -> 0.027671934 | D5: =LN('Historical Data'!D6/'Historical Data'!D5) -> 0.086469641 | E5: =LN('Historical Data'!E6/'Historical Data'!E5) -> -0.0010034977 | F5: =LN('Historical Data'!F6/'Historical Data'!F5) -> 0.058939717 | G5: =LN('Historical Data'!G6/'Historical Data'!G5) -> -0.013851286 | H5: =LN('Historical Data'!H6/'Historical Data'!H5) -> 0.040879424 | I5: =LN('Historical Data'!I6/'Historical Data'!I5) -> -0.026195775 | ... K5: =LN('Historical Data'!K6/'Historical Data'!K5) -> 0.21773062 | M5: 2023 | N5: =(((1+AVERAGE(D31:D42))^12)-1)*47.5% -> 0.48453739 | O5: =(((1+AVERAGE(J31:J42))^12)-1)*19.81% -> 0.055201673 | P5: =(((1+AVERAGE(E31:E42))^12)-1)*14.45% -> 0.059304015 | Q5: =(((1+AVERAGE(F31:F42))^12)-1)*12.04% -> 0.026197457 | R5: =(((1+AVERAGE(I31:I42))^12)-1)*3.6% -> 0.071718215 | S5: =(((1+AVERAGE(B31:B42))^12)-1)*2.6% -> 0.0073269665 | T5: =SUM(N5:S5) -> 0.70428572 | U5: =U4*(1+T5) -> 30758.776
A6: 44166 | B6: =LN('Historical Data'!B7/'Historical Data'!B6) -> -0.0055166638 | C6: =LN('Historical Data'!C7/'Historical Data'!C6) -> -0.015698599 | D6: =LN('Historical Data'!D7/'Historical Data'!D6) -> 0.03696663 | E6: =LN('Historical Data'!E7/'Historical Data'!E6) -> 0.041748863 | F6: =LN('Historical Data'!F7/'Historical Data'!F6) -> -0.12090838 | G6: =LN('Historical Data'!G7/'Historical Data'!G6) -> -0.055819713 | H6: =LN('Historical Data'!H7/'Historical Data'!H6) -> 0.041997263 | I6: =LN('Historical Data'!I7/'Historical Data'!I6) -> -0.0047155749 | ... K6: =LN('Historical Data'!K7/'Historical Data'!K6) -> 0.11734378 | M6: 2024 | N6: =(((1+AVERAGE(D43:D54))^12)-1)*47.5% -> 0.41285188 | O6: =(((1+AVERAGE(J43:J54))^12)-1)*19.81% -> 0.10487483 | P6: =(((1+AVERAGE(E43:E54))^12)-1)*14.45% -> 0.065452883 | Q6: =(((1+AVERAGE(F43:F54))^12)-1)*12.04% -> 0.029031651 | R6: =(((1+AVERAGE(I43:I54))^12)-1)*3.6% -> 0.033021961 | S6: =(((1+AVERAGE(B43:B54))^12)-1)*2.6% -> 0.0073516317 | T6: =SUM(N6:S6) -> 0.65258484 | U6: =U5*(1+T6) -> 50831.487
A7: 44197 | B7: =LN('Historical Data'!B8/'Historical Data'!B7) -> -0.084561528 | C7: =LN('Historical Data'!C8/'Historical Data'!C7) -> -0.035967574 | D7: =LN('Historical Data'!D8/'Historical Data'!D7) -> 0.042097648 | E7: =LN('Historical Data'!E8/'Historical Data'!E7) -> 0.10117023 | F7: =LN('Historical Data'!F8/'Historical Data'!F7) -> 0.11348062 | G7: =LN('Historical Data'!G8/'Historical Data'!G7) -> -0.0027524014 | H7: =LN('Historical Data'!H8/'Historical Data'!H7) -> 0.0018091946 | I7: =LN('Historical Data'!I8/'Historical Data'!I7) -> 0.054293258 | ... K7: =LN('Historical Data'!K8/'Historical Data'!K7) -> -0.16103804 | M7: 2025 | N7: =(((1+AVERAGE(D55:D63))^12)-1)*47.5% -> 0.40821342 | O7: =(((1+AVERAGE(J55:J63))^12)-1)*19.81% -> 0.24250314 | P7: =(((1+AVERAGE(E55:E63))^12)-1)*14.45% -> 0.04665533 | Q7: =(((1+AVERAGE(F55:F63))^12)-1)*12.04% -> -0.00069065824 | R7: =(((1+AVERAGE(I55:I63))^12)-1)*3.6% -> 0.025843523 | S7: =(((1+AVERAGE(B55:B63))^12)-1)*2.6% -> 0.0018212167 | T7: =SUM(N7:S7) -> 0.72434597 | U7: =U6*(1+T7) -> 87651.07 | Y7: Année | Z7: SEEGX (JPMorgan Large Cap Growth I) | AA7: Russell 1000 (Total Return) | AB7: MSCI World (Net TR, USD) | AC7: Group Portfolio | AD7: SEEGX | AE7: Russell 1000 | AF7: MSCI World | AG7: Group Portfolio
A8: 44228 | B8: =LN('Historical Data'!B9/'Historical Data'!B8) -> 0.0088054105 | C8: =LN('Historical Data'!C9/'Historical Data'!C8) -> 0.00037174662 | D8: =LN('Historical Data'!D9/'Historical Data'!D8) -> -0.013304414 | E8: =LN('Historical Data'!E9/'Historical Data'!E8) -> 0.019886013 | F8: =LN('Historical Data'!F9/'Historical Data'!F8) -> 0.0061978114 | G8: =LN('Historical Data'!G9/'Historical Data'!G8) -> 0.13389504 | H8: =LN('Historical Data'!H9/'Historical Data'!H8) -> 0.016783528 | I8: =LN('Historical Data'!I9/'Historical Data'!I8) -> -0.027068136 | ... K8: =LN('Historical Data'!K9/'Historical Data'!K8) -> -0.011270078 | Y8: 2020 | AD8: 10000 | AE8: 10000 | AF8: 10000 | AG8: 10000 | AJ8: Year | AK8: 2020 | AL8: 2021 | AM8: 2022 | AN8: 2023 | AO8: 2024 | AP8: 2025
A9: 44256 | B9: =LN('Historical Data'!B10/'Historical Data'!B9) -> 0.073452977 | C9: =LN('Historical Data'!C10/'Historical Data'!C9) -> 0.11392019 | D9: =LN('Historical Data'!D10/'Historical Data'!D9) -> -0.0084339227 | E9: =LN('Historical Data'!E10/'Historical Data'!E9) -> 0.13197469 | F9: =LN('Historical Data'!F10/'Historical Data'!F9) -> 0.070506761 | G9: =LN('Historical Data'!G10/'Historical Data'!G9) -> 0.098690383 | H9: =LN('Historical Data'!H10/'Historical Data'!H9) -> 0.067286132 | I9: =LN('Historical Data'!I10/'Historical Data'!I9) -> 0.11764313 | ... K9: =LN('Historical Data'!K10/'Historical Data'!K9) -> 0.060292699 | Y9: 2021 | Z9: 0.5604 | AA9: 0.2096 | AB9: 0.159 | AC9: 0.58095069 | AD9: =AD8*(1+Z9) -> 15604 | AE9: =AE8*(1+AA9) -> 12096 | AF9: =AF8*(1+AB9) -> 11590 | AG9: =AG8*(1+AC9) -> 15809.507 | AJ9: Performance of the year | AK9: 0.58095069 | AL9: 0.3645085 | AM9: -0.16337261 | AN9: 0.70428572 | AO9: 0.65258484 | AP9: 0.72434597
A10: 44287 | B10: =LN('Historical Data'!B11/'Historical Data'!B10) -> -0.053513878 | C10: =LN('Historical Data'!C11/'Historical Data'!C10) -> -0.07307648 | D10: =LN('Historical Data'!D11/'Historical Data'!D10) -> 0.034746641 | E10: =LN('Historical Data'!E11/'Historical Data'!E10) -> 0.001422805 | F10: =LN('Historical Data'!F11/'Historical Data'!F10) -> -0.056677504 | G10: =LN('Historical Data'!G11/'Historical Data'!G10) -> 0.011165635 | H10: =LN('Historical Data'!H11/'Historical Data'!H10) -> -0.0099631258 | I10: =LN('Historical Data'!I11/'Historical Data'!I10) -> 0.079071027 | ... K10: =LN('Historical Data'!K11/'Historical Data'!K10) -> -0.12637218 | Y10: 2022 | Z10: 0.1849 | AA10: 0.2646 | AB10: 0.2182 | AC10: 0.3645085 | AD10: =AD9*(1+Z10) -> 18489.18 | AE10: =AE9*(1+AA10) -> 15296.602 | AF10: =AF9*(1+AB10) -> 14118.938 | AG10: =AG9*(1+AC10) -> 21572.207
A11: 44317 | B11: =LN('Historical Data'!B12/'Historical Data'!B11) -> 0.096197265 | C11: =LN('Historical Data'!C12/'Historical Data'!C11) -> 0.06518366 | D11: =LN('Historical Data'!D12/'Historical Data'!D11) -> 0.0095029545 | E11: =LN('Historical Data'!E12/'Historical Data'!E11) -> 0.035405323 | F11: =LN('Historical Data'!F12/'Historical Data'!F11) -> 0.012429888 | G11: =LN('Historical Data'!G12/'Historical Data'!G11) -> 0.056132021 | H11: =LN('Historical Data'!H12/'Historical Data'!H11) -> 0.083875861 | I11: =LN('Historical Data'!I12/'Historical Data'!I11) -> 0.20810268 | ... K11: =LN('Historical Data'!K12/'Historical Data'!K11) -> 0.083547924 | M11: Holdings | N11: Colonne1 | O11: Colonne2 | Y11: 2023 | Z11: -0.2541 | AA11: -0.1913 | AB11: -0.1814 | AC11: -0.16337261 | AD11: =AD10*(1+Z11) -> 13791.079 | AE11: =AE10*(1+AA11) -> 12370.362 | AF11: =AF10*(1+AB11) -> 11557.763 | AG11: =AG10*(1+AC11) -> 18047.899
A12: 44348 | B12: =LN('Historical Data'!B13/'Historical Data'!B12) -> 0.062958103 | C12: =LN('Historical Data'!C13/'Historical Data'!C12) -> -0.033269664 | D12: =LN('Historical Data'!D13/'Historical Data'!D12) -> 0.025589715 | E12: =LN('Historical Data'!E13/'Historical Data'!E12) -> 0.098492132 | F12: =LN('Historical Data'!F13/'Historical Data'!F12) -> 0.055538043 | G12: =LN('Historical Data'!G13/'Historical Data'!G12) -> 0.024404077 | H12: =LN('Historical Data'!H13/'Historical Data'!H12) -> 0.050423955 | I12: =LN('Historical Data'!I13/'Historical Data'!I12) -> -0.025264868 | ... K12: =LN('Historical Data'!K13/'Historical Data'!K12) -> 0.010973845 | M12: Top 10 (%) | Y12: 2024 | Z12: 0.3462 | AA12: 0.2653 | AB12: 0.2379 | AC12: 0.70428572 | AD12: =AD11*(1+Z12) -> 18565.551 | AE12: =AE11*(1+AA12) -> 15652.219 | AF12: =AF11*(1+AB12) -> 14307.354 | AG12: =AG11*(1+AC12) -> 30758.776
A13: 44378 | B13: =LN('Historical Data'!B14/'Historical Data'!B13) -> 0.040114686 | C13: =LN('Historical Data'!C14/'Historical Data'!C13) -> 0.042133915 | D13: =LN('Historical Data'!D14/'Historical Data'!D13) -> 0.024039014 | E13: =LN('Historical Data'!E14/'Historical Data'!E13) -> 0.07139858 | F13: =LN('Historical Data'!F14/'Historical Data'!F13) -> -0.1074009 | G13: =LN('Historical Data'!G14/'Historical Data'!G13) -> 0.062765307 | H13: =LN('Historical Data'!H14/'Historical Data'!H13) -> 0.057856252 | I13: =LN('Historical Data'!I14/'Historical Data'!I13) -> 0.13802791 | ... K13: =LN('Historical Data'!K14/'Historical Data'!K13) -> 0.068224095 | M13: AVGO | O13: 0.47501974 | Y13: 2025 | Z13: 0.3384 | AA13: 0.2451 | AB13: 0.1867 | AC13: 0.65258484 | AD13: =AD12*(1+Z13) -> 24848.133 | AE13: =AE12*(1+AA13) -> 19488.577 | AF13: =AF12*(1+AB13) -> 16978.537 | AG13: =AG12*(1+AC13) -> 50831.487
A14: 44409 | B14: =LN('Historical Data'!B15/'Historical Data'!B14) -> -0.068965054 | C14: =LN('Historical Data'!C15/'Historical Data'!C14) -> -0.055003405 | D14: =LN('Historical Data'!D15/'Historical Data'!D14) -> -0.025007807 | E14: =LN('Historical Data'!E15/'Historical Data'!E14) -> -0.079226387 | F14: =LN('Historical Data'!F15/'Historical Data'!F14) -> 0.0041790867 | G14: =LN('Historical Data'!G15/'Historical Data'!G14) -> -0.11138822 | H14: =LN('Historical Data'!H15/'Historical Data'!H14) -> -0.066493568 | I14: =LN('Historical Data'!I15/'Historical Data'!I14) -> -0.077308267 | ... K14: =LN('Historical Data'!K15/'Historical Data'!K14) -> 0.052632452 | M14: ORCL | O14: 0.19808035 | Y14: 2026 | Z14: 0.1628 | AA14: 0.1722 | AB14: 0.1952 | AC14: 0.72434597 | AD14: =AD13*(1+Z14) -> 28893.409 | AE14: =AE13*(1+AA14) -> 22844.511 | AF14: =AF13*(1+AB14) -> 20292.748 | AG14: =AG13*(1+AC14) -> 87651.07
A15: 44440 | B15: =LN('Historical Data'!B16/'Historical Data'!B15) -> 0.05700147 | C15: =LN('Historical Data'!C16/'Historical Data'!C15) -> 0.026254724 | D15: =LN('Historical Data'!D16/'Historical Data'!D15) -> 0.09932043 | E15: =LN('Historical Data'!E16/'Historical Data'!E15) -> 0.10210432 | F15: =LN('Historical Data'!F16/'Historical Data'!F15) -> -0.035601216 | G15: =LN('Historical Data'!G16/'Historical Data'!G15) -> -0.047734188 | H15: =LN('Historical Data'!H16/'Historical Data'!H15) -> 0.16236607 | I15: =LN('Historical Data'!I16/'Historical Data'!I15) -> 0.21039578 | ... K15: =LN('Historical Data'!K16/'Historical Data'!K15) -> 0.36223027 | M15: GOOGL | O15: 0.14450369
A16: 44470 | B16: =LN('Historical Data'!B17/'Historical Data'!B16) -> 0.098460956 | C16: =LN('Historical Data'!C17/'Historical Data'!C16) -> 0.039147378 | D16: =LN('Historical Data'!D17/'Historical Data'!D16) -> 0.040563925 | E16: =LN('Historical Data'!E17/'Historical Data'!E16) -> -0.042418188 | F16: =LN('Historical Data'!F17/'Historical Data'!F16) -> -0.062100155 | G16: =LN('Historical Data'!G17/'Historical Data'!G16) -> 0.0027463314 | H16: =LN('Historical Data'!H17/'Historical Data'!H16) -> -0.003110635 | I16: =LN('Historical Data'!I17/'Historical Data'!I16) -> 0.2453387 | ... K16: =LN('Historical Data'!K17/'Historical Data'!K16) -> 0.027238044 | M16: MA | O16: 0.12041574
A17: 44501 | B17: =LN('Historical Data'!B18/'Historical Data'!B17) -> 0.073061759 | C17: =LN('Historical Data'!C18/'Historical Data'!C17) -> -0.050506172 | D17: =LN('Historical Data'!D18/'Historical Data'!D17) -> 0.18381659 | E17: =LN('Historical Data'!E18/'Historical Data'!E17) -> 0.020607832 | F17: =LN('Historical Data'!F18/'Historical Data'!F17) -> 0.13189485 | G17: =LN('Historical Data'!G18/'Historical Data'!G17) -> 0.035990176 | H17: =LN('Historical Data'!H18/'Historical Data'!H17) -> 0.019012103 | I17: =LN('Historical Data'!I18/'Historical Data'!I17) -> -0.1052721 | ... K17: =LN('Historical Data'!K18/'Historical Data'!K17) -> -0.079968546 | M17: NVDA | O17: 0.035991037
A18: 44531 | B18: =LN('Historical Data'!B19/'Historical Data'!B18) -> -0.015837295 | C18: =LN('Historical Data'!C19/'Historical Data'!C18) -> -0.10850985 | D18: =LN('Historical Data'!D19/'Historical Data'!D18) -> -0.1209119 | E18: =LN('Historical Data'!E19/'Historical Data'!E18) -> -0.068192164 | F18: =LN('Historical Data'!F19/'Historical Data'!F18) -> 0.072608057 | G18: =LN('Historical Data'!G19/'Historical Data'!G18) -> -0.071118676 | H18: =LN('Historical Data'!H19/'Historical Data'!H18) -> -0.07833467 | I18: =LN('Historical Data'!I19/'Historical Data'!I18) -> -0.18314487 | ... K18: =LN('Historical Data'!K19/'Historical Data'!K18) -> -0.12059742 | M18: AAPL | O18: 0.025989442
A19: 44562 | B19: =LN('Historical Data'!B20/'Historical Data'!B19) -> -0.056855614 | C19: =LN('Historical Data'!C20/'Historical Data'!C19) -> 0.026322995 | D19: =LN('Historical Data'!D20/'Historical Data'!D19) -> 0.0026592593 | E19: =LN('Historical Data'!E20/'Historical Data'!E19) -> -0.0018234058 | F19: =LN('Historical Data'!F20/'Historical Data'!F19) -> -0.067130806 | G19: =LN('Historical Data'!G20/'Historical Data'!G19) -> -0.39503345 | H19: =LN('Historical Data'!H20/'Historical Data'!H19) -> -0.039987578 | I19: =LN('Historical Data'!I20/'Historical Data'!I19) -> -0.0041333225 | ... K19: =LN('Historical Data'!K20/'Historical Data'!K19) -> -0.073397184 | M19: AMZN | O19: 0
A20: 44593 | B20: =LN('Historical Data'!B21/'Historical Data'!B20) -> 0.057156115 | C20: =LN('Historical Data'!C21/'Historical Data'!C20) -> 0.059623957 | D20: =LN('Historical Data'!D21/'Historical Data'!D20) -> 0.069437527 | E20: =LN('Historical Data'!E21/'Historical Data'!E20) -> 0.029262303 | F20: =LN('Historical Data'!F21/'Historical Data'!F20) -> -0.0095796487 | G20: =LN('Historical Data'!G21/'Historical Data'!G20) -> 0.052297477 | H20: =LN('Historical Data'!H21/'Historical Data'!H20) -> 0.033430313 | I20: =LN('Historical Data'!I21/'Historical Data'!I20) -> 0.11240547 | ... K20: =LN('Historical Data'!K21/'Historical Data'!K20) -> 0.2135044 | M20: META | O20: 0
A21: 44621 | B21: =LN('Historical Data'!B22/'Historical Data'!B21) -> -0.10217803 | C21: =LN('Historical Data'!C22/'Historical Data'!C21) -> -0.27118571 | D21: =LN('Historical Data'!D22/'Historical Data'!D21) -> -0.12060406 | E21: =LN('Historical Data'!E22/'Historical Data'!E21) -> -0.19780056 | F21: =LN('Historical Data'!F22/'Historical Data'!F21) -> 0.016649496 | G21: =LN('Historical Data'!G22/'Historical Data'!G21) -> -0.10363318 | H21: =LN('Historical Data'!H22/'Historical Data'!H21) -> -0.10521257 | I21: =LN('Historical Data'!I22/'Historical Data'!I21) -> -0.38589506 | ... K21: =LN('Historical Data'!K22/'Historical Data'!K21) -> -0.21312535 | M21: MSFT | O21: 0
A22: 44652 | B22: =LN('Historical Data'!B23/'Historical Data'!B22) -> -0.057505127 | C22: =LN('Historical Data'!C23/'Historical Data'!C22) -> -0.0333131 | D22: =LN('Historical Data'!D23/'Historical Data'!D22) -> 0.045384062 | E22: =LN('Historical Data'!E23/'Historical Data'!E22) -> -0.0030497919 | F22: =LN('Historical Data'!F23/'Historical Data'!F22) -> -0.013892154 | G22: =LN('Historical Data'!G23/'Historical Data'!G22) -> -0.034663575 | H22: =LN('Historical Data'!H23/'Historical Data'!H22) -> -0.020568987 | I22: =LN('Historical Data'!I23/'Historical Data'!I22) -> 0.0067172094 | ... K22: =LN('Historical Data'!K23/'Historical Data'!K22) -> -0.13834008 | M22: TSLA | O22: 0
A23: 44682 | B23: =LN('Historical Data'!B24/'Historical Data'!B23) -> -0.083468445 | C23: =LN('Historical Data'!C24/'Historical Data'!C23) -> -0.12381779 | D23: =LN('Historical Data'!D24/'Historical Data'!D23) -> -0.17743479 | E23: =LN('Historical Data'!E24/'Historical Data'!E23) -> -0.04310082 | F23: =LN('Historical Data'!F24/'Historical Data'!F23) -> -0.12607488 | G23: =LN('Historical Data'!G24/'Historical Data'!G23) -> -0.18304511 | H23: =LN('Historical Data'!H24/'Historical Data'!H23) -> -0.054583395 | I23: =LN('Historical Data'!I24/'Historical Data'!I23) -> -0.20843119 | ... K23: =LN('Historical Data'!K24/'Historical Data'!K23) -> -0.11865715
A24: 44713 | B24: =LN('Historical Data'!B25/'Historical Data'!B24) -> 0.17280443 | C24: =LN('Historical Data'!C25/'Historical Data'!C24) -> 0.23948607 | D24: =LN('Historical Data'!D25/'Historical Data'!D24) -> 0.10560216 | E24: =LN('Historical Data'!E25/'Historical Data'!E24) -> 0.065336601 | F24: =LN('Historical Data'!F25/'Historical Data'!F24) -> 0.11460866 | G24: =LN('Historical Data'!G25/'Historical Data'!G24) -> -0.013422852 | H24: =LN('Historical Data'!H25/'Historical Data'!H24) -> 0.089014845 | I24: =LN('Historical Data'!I25/'Historical Data'!I24) -> 0.18100393 | ... K24: =LN('Historical Data'!K25/'Historical Data'!K24) -> 0.28048029
A25: 44743 | B25: =LN('Historical Data'!B26/'Historical Data'!B25) -> -0.033093632 | C25: =LN('Historical Data'!C26/'Historical Data'!C25) -> -0.062529919 | D25: =LN('Historical Data'!D26/'Historical Data'!D25) -> -0.070336943 | E25: =LN('Historical Data'!E26/'Historical Data'!E25) -> -0.072178687 | F25: =LN('Historical Data'!F26/'Historical Data'!F25) -> -0.085287674 | G25: =LN('Historical Data'!G26/'Historical Data'!G25) -> 0.023787517 | H25: =LN('Historical Data'!H26/'Historical Data'!H25) -> -0.071109623 | I25: =LN('Historical Data'!I26/'Historical Data'!I25) -> -0.18508942 | ... K25: =LN('Historical Data'!K26/'Historical Data'!K25) -> -0.075250239
A26: 44774 | B26: =LN('Historical Data'!B27/'Historical Data'!B26) -> -0.12755585 | C26: =LN('Historical Data'!C27/'Historical Data'!C26) -> -0.1149866 | D26: =LN('Historical Data'!D27/'Historical Data'!D26) -> -0.11697927 | E26: =LN('Historical Data'!E27/'Historical Data'!E26) -> -0.12347043 | F26: =LN('Historical Data'!F27/'Historical Data'!F26) -> -0.13171391 | G26: =LN('Historical Data'!G27/'Historical Data'!G26) -> -0.18302123 | H26: =LN('Historical Data'!H27/'Historical Data'!H26) -> -0.11358977 | I26: =LN('Historical Data'!I27/'Historical Data'!I26) -> -0.21787411 | ... K26: =LN('Historical Data'!K27/'Historical Data'!K26) -> -0.038314045
A27: 44805 | B27: =LN('Historical Data'!B28/'Historical Data'!B27) -> 0.10395492 | C27: =LN('Historical Data'!C28/'Historical Data'!C27) -> -0.098110557 | D27: =LN('Historical Data'!D28/'Historical Data'!D27) -> 0.065490892 | E27: =LN('Historical Data'!E28/'Historical Data'!E27) -> -0.011989928 | F27: =LN('Historical Data'!F28/'Historical Data'!F27) -> 0.14339138 | G27: =LN('Historical Data'!G28/'Historical Data'!G27) -> -0.37598069 | H27: =LN('Historical Data'!H28/'Historical Data'!H27) -> -0.003312013 | I27: =LN('Historical Data'!I28/'Historical Data'!I27) -> 0.10634099 | ... K27: =LN('Historical Data'!K28/'Historical Data'!K27) -> -0.15334673
A28: 44835 | B28: =LN('Historical Data'!B29/'Historical Data'!B28) -> -0.035242178 | C28: =LN('Historical Data'!C29/'Historical Data'!C28) -> -0.059319831 | D28: =LN('Historical Data'!D29/'Historical Data'!D28) -> 0.1588012 | E28: =LN('Historical Data'!E29/'Historical Data'!E28) -> 0.066315418 | F28: =LN('Historical Data'!F29/'Historical Data'!F28) -> 0.084103703 | G28: =LN('Historical Data'!G29/'Historical Data'!G28) -> 0.23721314 | H28: =LN('Historical Data'!H29/'Historical Data'!H28) -> 0.094514905 | I28: =LN('Historical Data'!I29/'Historical Data'!I28) -> 0.22620633 | ... K28: =LN('Historical Data'!K29/'Historical Data'!K28) -> -0.15586613 | AT28: Metric | AU28: Value | AV28: Interpretation (Group Portfolio)
A29: 44866 | B29: =LN('Historical Data'!B30/'Historical Data'!B29) -> -0.12876211 | C29: =LN('Historical Data'!C30/'Historical Data'!C29) -> -0.13914063 | D29: =LN('Historical Data'!D30/'Historical Data'!D29) -> 0.014592706 | E29: =LN('Historical Data'!E30/'Historical Data'!E29) -> -0.1350741 | F29: =LN('Historical Data'!F30/'Historical Data'!F29) -> -0.024627336 | G29: =LN('Historical Data'!G30/'Historical Data'!G29) -> 0.018789551 | H29: =LN('Historical Data'!H30/'Historical Data'!H29) -> -0.059109584 | I29: =LN('Historical Data'!I30/'Historical Data'!I29) -> -0.14643755 | ... K29: =LN('Historical Data'!K30/'Historical Data'!K29) -> -0.45781321 | AT29: Sharpe Ratio | AU29: 1.27 | AV29: Indicates strong risk-adjusted performance investors are well compensated for volatility.
A30: 44896 | B30: =LN('Historical Data'!B31/'Historical Data'!B30) -> 0.1048294 | C30: =LN('Historical Data'!C31/'Historical Data'!C30) -> 0.20517353 | D30: =LN('Historical Data'!D31/'Historical Data'!D30) -> 0.053556274 | E30: =LN('Historical Data'!E31/'Historical Data'!E30) -> 0.1135552 | F30: =LN('Historical Data'!F31/'Historical Data'!F30) -> 0.063696823 | G30: =LN('Historical Data'!G31/'Historical Data'!G30) -> 0.21342327 | H30: =LN('Historical Data'!H31/'Historical Data'!H30) -> 0.032773546 | I30: =LN('Historical Data'!I31/'Historical Data'!I30) -> 0.29033007 | ... K30: =LN('Historical Data'!K31/'Historical Data'!K30) -> 0.34091576 | AT30: Beta | AU30: 1.24 | AV30: Slightly more sensitive to market movements, reflecting higher exposure to growth stocks.
A31: 44927 | B31: =LN('Historical Data'!B32/'Historical Data'!B31) -> 0.021393284 | C31: =LN('Historical Data'!C32/'Historical Data'!C31) -> -0.090251726 | D31: =LN('Historical Data'!D32/'Historical Data'!D31) -> 0.01573847 | E31: =LN('Historical Data'!E32/'Historical Data'!E31) -> -0.093026072 | F31: =LN('Historical Data'!F32/'Historical Data'!F31) -> -0.040567227 | G31: =LN('Historical Data'!G32/'Historical Data'!G31) -> 0.16069828 | H31: =LN('Historical Data'!H32/'Historical Data'!H31) -> 0.0064761118 | I31: =LN('Historical Data'!I32/'Historical Data'!I31) -> 0.17253135 | ... K31: =LN('Historical Data'!K32/'Historical Data'!K31) -> 0.17190495 | AT31: Alpha | AU31: +0.185 | AV31: Positive excess return versus expected benchmark performance.
A32: 44958 | B32: =LN('Historical Data'!B33/'Historical Data'!B32) -> 0.11364681 | C32: =LN('Historical Data'!C33/'Historical Data'!C32) -> 0.091801964 | D32: =LN('Historical Data'!D33/'Historical Data'!D32) -> 0.076504017 | E32: =LN('Historical Data'!E33/'Historical Data'!E32) -> 0.14131551 | F32: =LN('Historical Data'!F33/'Historical Data'!F32) -> 0.022597183 | G32: =LN('Historical Data'!G33/'Historical Data'!G32) -> 0.1918602 | H32: =LN('Historical Data'!H33/'Historical Data'!H32) -> 0.14736474 | I32: =LN('Historical Data'!I33/'Historical Data'!I32) -> 0.17936695 | ... K32: =LN('Historical Data'!K33/'Historical Data'!K32) -> 0.00847114 | AT32: Treynor Ratio | AU32: 0.26 | AV32: Solid return per unit of market risk, showing efficient portfolio management.
A33: 44986 | B33: =LN('Historical Data'!B34/'Historical Data'!B33) -> 0.028574955 | C33: =LN('Historical Data'!C34/'Historical Data'!C33) -> 0.020696341 | D33: =LN('Historical Data'!D34/'Historical Data'!D33) -> -0.016550936 | E33: =LN('Historical Data'!E34/'Historical Data'!E33) -> 0.03420931 | F33: =LN('Historical Data'!F34/'Historical Data'!F33) -> 0.044718852 | G33: =LN('Historical Data'!G34/'Historical Data'!G33) -> 0.12566853 | H33: =LN('Historical Data'!H34/'Historical Data'!H33) -> 0.063693048 | I33: =LN('Historical Data'!I34/'Historical Data'!I33) -> -0.00083888706 | ... K33: =LN('Historical Data'!K34/'Historical Data'!K33) -> -0.23318366 | AT33: Standard Deviation | AU33: 0.25 | AV33: Moderate volatility consistent with a high-growth equity portfolio.
A34: 45017 | B34: =LN('Historical Data'!B35/'Historical Data'!B34) -> 0.043646741 | C34: =LN('Historical Data'!C35/'Historical Data'!C34) -> 0.13407653 | D34: =LN('Historical Data'!D35/'Historical Data'!D34) -> 0.25436365 | E34: =LN('Historical Data'!E35/'Historical Data'!E34) -> 0.1351262 | F34: =LN('Historical Data'!F35/'Historical Data'!F34) -> -0.038730776 | G34: =LN('Historical Data'!G35/'Historical Data'!G34) -> 0.096701275 | H34: =LN('Historical Data'!H35/'Historical Data'!H34) -> 0.066507592 | I34: =LN('Historical Data'!I35/'Historical Data'!I34) -> 0.31000847 | ... K34: =LN('Historical Data'!K35/'Historical Data'!K34) -> 0.21602191
A35: 45047 | B35: =LN('Historical Data'!B36/'Historical Data'!B35) -> 0.091525027 | C35: =LN('Historical Data'!C36/'Historical Data'!C35) -> 0.077986421 | D35: =LN('Historical Data'!D36/'Historical Data'!D35) -> 0.071022334 | E35: =LN('Historical Data'!E36/'Historical Data'!E35) -> -0.026138382 | F35: =LN('Historical Data'!F36/'Historical Data'!F35) -> 0.074620678 | G35: =LN('Historical Data'!G36/'Historical Data'!G35) -> 0.080739806 | H35: =LN('Historical Data'!H36/'Historical Data'!H35) -> 0.03851428 | I35: =LN('Historical Data'!I36/'Historical Data'!I35) -> 0.11162599 | ... K35: =LN('Historical Data'!K36/'Historical Data'!K35) -> 0.24968946
A36: 45078 | B36: =LN('Historical Data'!B37/'Historical Data'!B36) -> 0.01270427 | C36: =LN('Historical Data'!C37/'Historical Data'!C36) -> 0.02514903 | D36: =LN('Historical Data'!D37/'Historical Data'!D36) -> 0.040672274 | E36: =LN('Historical Data'!E37/'Historical Data'!E36) -> 0.1032529 | F36: =LN('Historical Data'!F37/'Historical Data'!F36) -> 0.002488642 | G36: =LN('Historical Data'!G37/'Historical Data'!G36) -> 0.10452397 | H36: =LN('Historical Data'!H37/'Historical Data'!H36) -> -0.013659572 | I36: =LN('Historical Data'!I37/'Historical Data'!I36) -> 0.099634252 | ... K36: =LN('Historical Data'!K37/'Historical Data'!K36) -> 0.021391594
A37: 45108 | B37: =LN('Historical Data'!B38/'Historical Data'!B37) -> -0.044657623 | C37: =LN('Historical Data'!C38/'Historical Data'!C37) -> 0.031877262 | D37: =LN('Historical Data'!D38/'Historical Data'!D37) -> 0.026616364 | E37: =LN('Historical Data'!E38/'Historical Data'!E37) -> 0.025662693 | F37: =LN('Historical Data'!F38/'Historical Data'!F37) -> 0.046959346 | G37: =LN('Historical Data'!G38/'Historical Data'!G37) -> -0.073948769 | H37: =LN('Historical Data'!H38/'Historical Data'!H37) -> -0.024591492 | I37: =LN('Historical Data'!I38/'Historical Data'!I37) -> 0.054674179 | ... K37: =LN('Historical Data'!K38/'Historical Data'!K37) -> -0.035588235
A38: 45139 | B38: =LN('Historical Data'!B39/'Historical Data'!B38) -> -0.091509863 | C38: =LN('Historical Data'!C39/'Historical Data'!C38) -> -0.082194624 | D38: =LN('Historical Data'!D39/'Historical Data'!D38) -> -0.10538582 | E38: =LN('Historical Data'!E39/'Historical Data'!E38) -> -0.039776602 | F38: =LN('Historical Data'!F39/'Historical Data'!F38) -> -0.041388584 | G38: =LN('Historical Data'!G39/'Historical Data'!G38) -> 0.014494695 | H38: =LN('Historical Data'!H39/'Historical Data'!H38) -> -0.03521588 | I38: =LN('Historical Data'!I39/'Historical Data'!I38) -> -0.12630115 | ... K38: =LN('Historical Data'!K39/'Historical Data'!K38) -> -0.030929083
A39: 45170 | B39: =LN('Historical Data'!B40/'Historical Data'!B39) -> -0.0025730615 | C39: =LN('Historical Data'!C40/'Historical Data'!C39) -> 0.045894069 | D39: =LN('Historical Data'!D40/'Historical Data'!D39) -> 0.018338872 | E39: =LN('Historical Data'!E40/'Historical Data'!E39) -> -0.053201072 | F39: =LN('Historical Data'!F40/'Historical Data'!F39) -> -0.050667569 | G39: =LN('Historical Data'!G40/'Historical Data'!G39) -> 0.0035242899 | H39: =LN('Historical Data'!H40/'Historical Data'!H39) -> 0.068420411 | I39: =LN('Historical Data'!I40/'Historical Data'!I39) -> -0.064463867 | ... K39: =LN('Historical Data'!K40/'Historical Data'!K39) -> -0.21983196
A40: 45200 | B40: =LN('Historical Data'!B41/'Historical Data'!B40) -> 0.10644293 | C40: =LN('Historical Data'!C41/'Historical Data'!C40) -> 0.093197279 | D40: =LN('Historical Data'!D41/'Historical Data'!D40) -> 0.095551185 | E40: =LN('Historical Data'!E41/'Historical Data'!E40) -> 0.065882358 | F40: =LN('Historical Data'!F41/'Historical Data'!F40) -> 0.096384505 | G40: =LN('Historical Data'!G41/'Historical Data'!G40) -> 0.082412119 | H40: =LN('Historical Data'!H41/'Historical Data'!H40) -> 0.11392751 | I40: =LN('Historical Data'!I41/'Historical Data'!I40) -> 0.13705017 | ... K40: =LN('Historical Data'!K41/'Historical Data'!K40) -> 0.17846363
...

Sheet Var-covar Matrix
B1: Colonne 1 | C1: Colonne 2 | D1: Colonne 3 | E1: Colonne 4 | F1: Colonne 5 | G1: Colonne 6 | H1: Colonne 7 | I1: Colonne 8 | J1: Colonne 9 | K1: Colonne 10
A2: Colonne 1 | B2: =VARP('Expected Return'!$B$3:$B$63) -> 0.0050127027 | C2: 0.0034166012 | D2: 0.0028859183 | E2: 0.0023801412 | F2: 0.0019422612 | G2: 0.0020103695 | H2: 0.0023098488 | I2: 0.005254531 | J2: 0.0029820701 | K2: 0.0071044219
A3: Colonne 2 | B3: 0.0034166012 | C3: =VARP('Expected Return'!$C$3:$C$63) -> 0.0074741095 | D3: 0.0044280013 | E3: 0.0042508734 | F3: 0.001598934 | G3: 0.0048671486 | H3: 0.0035317041 | I3: 0.0084081394 | J3: 0.0038913778 | K3: 0.0088870296
A4: Colonne 3 | B4: 0.0028859183 | C4: 0.0044280013 | D4: =VARP('Expected Return'!$D$3:$D$63) -> 0.0096221283 | E4: 0.0043102942 | F4: 0.0019556877 | G4: 0.0043341974 | H4: 0.0035713869 | I4: 0.0076542009 | J4: 0.0042759542 | K4: 0.0069652438
A5: Colonne 4 | B5: 0.0023801412 | C5: 0.0042508734 | D5: 0.0043102942 | E5: =VARP('Expected Return'!$E$3:$E$63) -> 0.0060091084 | F5: 0.00084652633 | G5: 0.0032294898 | H5: 0.0027771745 | I5: 0.0058758386 | J5: 0.0031718375 | K5: 0.0061772717
A6: Colonne 5 | B6: 0.0019422612 | C6: 0.001598934 | D6: 0.0019556877 | E6: 0.00084652633 | F6: =VARP('Expected Return'!$F$3:$F$63) -> 0.0046605782 | G6: 0.001881243 | H6: 0.0012293047 | I6: 0.0023521436 | J6: 0.0024031466 | K6: 0.0018411617
A7: Colonne 6 | B7: 0.0020103695 | C7: 0.0048671486 | D7: 0.0043341974 | E7: 0.0032294898 | F7: 0.001881243 | G7: =VARP('Expected Return'!$G$3:$G$63) -> 0.014162001 | H7: 0.0039243088 | I7: 0.0080628732 | J7: 0.0033457118 | K7: 0.0043524846
A8: Colonne 7 | B8: 0.0023098488 | C8: 0.0035317041 | D8: 0.0035713869 | E8: 0.0027771745 | F8: 0.0012293047 | G8: 0.0039243088 | H8: =VARP('Expected Return'!$H$3:$H$63) -> 0.0038336689 | I8: 0.006213743 | J8: 0.0038736062 | K8: 0.0044338242
A9: Colonne 8 | B9: 0.005254531 | C9: 0.0084081394 | D9: 0.0076542009 | E9: 0.0058758386 | F9: 0.0023521436 | G9: 0.0080628732 | H9: 0.006213743 | I9: =VARP('Expected Return'!$I$3:$I$63) -> 0.019596192 | J9: 0.0075630919 | K9: 0.0095879738
A10: Colonne 9 | B10: 0.0029820701 | C10: 0.0038913778 | D10: 0.0042759542 | E10: 0.0031718375 | F10: 0.0024031466 | G10: 0.0033457118 | H10: 0.0038736062 | I10: 0.0075630919 | J10: =VARP('Expected Return'!$J$3:$J$63) -> 0.009793327 | K10: 0.0050815539
A11: Colonne 10 | B11: 0.0071044219 | C11: 0.0088870296 | D11: 0.0069652438 | E11: 0.0061772717 | F11: 0.0018411617 | G11: 0.0043524846 | H11: 0.0044338242 | I11: 0.0095879738 | J11: 0.0050815539 | K11: =VARP('Expected Return'!$K$3:$K$63) -> 0.030555444
H20: 0.0034166012 | I20: 0.0028859183 | J20: 0.0023801412 | K20: 0.0019422612 | L20: 0.0020103695 | M20: 0.0023098488 | N20: 0.005254531 | O20: 0.0029820701 | P20: 0.0071044219
I21: 0.0044280013 | J21: 0.0042508734 | K21: 0.001598934 | L21: 0.0048671486 | M21: 0.0035317041 | N21: 0.0084081394 | O21: 0.0038913778 | P21: 0.0088870296
J22: 0.0043102942 | K22: 0.0019556877 | L22: 0.0043341974 | M22: 0.0035713869 | N22: 0.0076542009 | O22: 0.0042759542 | P22: 0.0069652438
K23: 0.00084652633 | L23: 0.0032294898 | M23: 0.0027771745 | N23: 0.0058758386 | O23: 0.0031718375 | P23: 0.0061772717
L24: 0.001881243 | M24: 0.0012293047 | N24: 0.0023521436 | O24: 0.0024031466 | P24: 0.0018411617
M25: 0.0039243088 | N25: 0.0080628732 | O25: 0.0033457118 | P25: 0.0043524846
N26: 0.006213743 | O26: 0.0038736062 | P26: 0.0044338242
O27: 0.0075630919 | P27: 0.0095879738
P28: 0.0050815539

Sheet Efficient portfolio frontier
B3: monthly var-covar matrix | E3: AAPL | F3: AMZN | G3: AVGO | H3: GOOGL | I3: MA | J3: META | K3: MSFT | L3: NVDA | M3: ORCL | N3: TSLA
D4: AAPL | E4: =VARP('Expected Return'!$B$3:$B$63) -> 0.0050127027 | F4: 0.0034166012 | G4: 0.0028859183 | H4: 0.0023801412 | I4: 0.0019422612 | J4: 0.0020103695 | K4: 0.0023098488 | L4: 0.005254531 | M4: 0.0029820701 | N4: 0.0071044219
D5: AMZN | E5: 0.0034166012 | F5: =VARP('Expected Return'!$C$3:$C$63) -> 0.0074741095 | G5: 0.0044280013 | H5: 0.0042508734 | I5: 0.001598934 | J5: 0.0048671486 | K5: 0.0035317041 | L5: 0.0084081394 | M5: 0.0038913778 | N5: 0.0088870296
D6: AVGO | E6: 0.0028859183 | F6: 0.0044280013 | G6: =VARP('Expected Return'!$D$3:$D$63) -> 0.0096221283 | H6: 0.0043102942 | I6: 0.0019556877 | J6: 0.0043341974 | K6: 0.0035713869 | L6: 0.0076542009 | M6: 0.0042759542 | N6: 0.0069652438
D7: GOOGL | E7: 0.0023801412 | F7: 0.0042508734 | G7: 0.0043102942 | H7: =VARP('Expected Return'!$E$3:$E$63) -> 0.0060091084 | I7: 0.00084652633 | J7: 0.0032294898 | K7: 0.0027771745 | L7: 0.0058758386 | M7: 0.0031718375 | N7: 0.0061772717
D8: MA | E8: 0.0019422612 | F8: 0.001598934 | G8: 0.0019556877 | H8: 0.00084652633 | I8: =VARP('Expected Return'!$F$3:$F$63) -> 0.0046605782 | J8: 0.001881243 | K8: 0.0012293047 | L8: 0.0023521436 | M8: 0.0024031466 | N8: 0.0018411617
D9: META | E9: 0.0020103695 | F9: 0.0048671486 | G9: 0.0043341974 | H9: 0.0032294898 | I9: 0.001881243 | J9: =VARP('Expected Return'!$G$3:$G$63) -> 0.014162001 | K9: 0.0039243088 | L9: 0.0080628732 | M9: 0.0033457118 | N9: 0.0043524846
D10: MSFT | E10: 0.0023098488 | F10: 0.0035317041 | G10: 0.0035713869 | H10: 0.0027771745 | I10: 0.0012293047 | J10: 0.0039243088 | K10: =VARP('Expected Return'!$H$3:$H$63) -> 0.0038336689 | L10: 0.006213743 | M10: 0.0038736062 | N10: 0.0044338242
D11: NVDA | E11: 0.005254531 | F11: 0.0084081394 | G11: 0.0076542009 | H11: 0.0058758386 | I11: 0.0023521436 | J11: 0.0080628732 | K11: 0.006213743 | L11: =VARP('Expected Return'!$I$3:$I$63) -> 0.019596192 | M11: 0.0075630919 | N11: 0.0095879738
D12: ORCL | E12: 0.0029820701 | F12: 0.0038913778 | G12: 0.0042759542 | H12: 0.0031718375 | I12: 0.0024031466 | J12: 0.0033457118 | K12: 0.0038736062 | L12: 0.0075630919 | M12: =VARP('Expected Return'!$J$3:$J$63) -> 0.009793327 | N12: 0.0050815539
D13: TSLA | E13: 0.0071044219 | F13: 0.0088870296 | G13: 0.0069652438 | H13: 0.0061772717 | I13: 0.0018411617 | J13: 0.0043524846 | K13: 0.0044338242 | L13: 0.0095879738 | M13: 0.0050815539 | N13: =VARP('Expected Return'!$K$3:$K$63) -> 0.030555444 | T13: Portfolio
Q14: annual MEAN RETURN | T14: AAPL | U14: AMZN | V14: AVGO | W14: GOOGL | X14: MA | Y14: META | Z14: MSFT | AA14: NVDA | AB14: ORCL | AC14: TSLA
B15: Annual var-covar matrix | E15: AAPL | F15: AMZN | G15: AVGO | H15: GOOGL | I15: MA | J15: META | K15: MSFT | L15: NVDA | M15: ORCL | N15: TSLA | T15: omega 1 | U15: omega 2 | V15: omega 3 | W15: omega 4 | X15: omega 5 | Y15: omega 6 | Z15: omega 7 | AA15: omega 8 | AB15: omega 9 | AC15: omega 10 | AD15: Mean | AE15: Var | AF15: Sigma | AG15: Constraint on weights | AH15: A | AI15: Utility
D16: AAPL | E16: {=E4:N13*12} -> 0.060152432 | F16: 0.040999214 | G16: 0.034631019 | H16: 0.028561695 | I16: 0.023307134 | J16: 0.024124434 | K16: 0.027718186 | L16: 0.063054372 | M16: 0.035784841 | N16: 0.085253063 | Q16: 0.1548038 | T16: 0.043668874 | U16: 0 | V16: 0.44525003 | W16: 0.15763666 | X16: 0.13973266 | Y16: 0 | Z16: 0 | AA16: 0.025123424 | AB16: 0.18858835 | AC16: 0 | AD16: =MMULT(Weights,Means) -> 0.34628278 | AE16: {=MMULT(Weights,MMULT(varcov,TRANSPOSE(Weights)))} -> 0.059669621 | AF16: =SQRT(AE16) -> 0.24427366 | AG16: =SUM(Weights) -> 1 | AH16: 750 | AI16: =AD16-0.005*AH16*AE16 -> 0.1225217
D17: AMZN | E17: 0.040999214 | F17: 0.089689313 | G17: 0.053136016 | H17: 0.05101048 | I17: 0.019187208 | J17: 0.058405784 | K17: 0.04238045 | L17: 0.10089767 | M17: 0.046696533 | N17: 0.10664435 | Q17: 0.060815934
D18: AVGO | E18: 0.034631019 | F18: 0.053136016 | G18: 0.11546554 | H18: 0.05172353 | I18: 0.023468252 | J18: 0.052010369 | K18: 0.042856643 | L18: 0.09185041 | M18: 0.051311451 | N18: 0.083582926 | Q18: 0.4712889
D19: GOOGL | E19: 0.028561695 | F19: 0.05101048 | G19: 0.05172353 | H19: 0.072109301 | I19: 0.010158316 | J19: 0.038753877 | K19: 0.033326094 | L19: 0.070510063 | M19: 0.03806205 | N19: 0.07412726 | Q19: 0.24390879 | S19: Initial portfolio | T19: 0.1 | U19: 0.1 | V19: 0.1 | W19: 0.1 | X19: 0.1 | Y19: 0.1 | Z19: 0.1 | AA19: 0.1 | AB19: 0.1 | AC19: 0.1 | AD19: 0.24815369 | AE19: 0.059232066 | AF19: 0.24337639 | AG19: 1
D20: MA | E20: 0.023307134 | F20: 0.019187208 | G20: 0.023468252 | H20: 0.010158316 | I20: 0.055926939 | J20: 0.022574916 | K20: 0.014751656 | L20: 0.028225724 | M20: 0.02883776 | N20: 0.02209394 | Q20: 0.10143547 | S20: GMVP | T20: 0.1241732 | U20: 0 | V20: 0 | W20: 0.15590754 | X20: 0.36807696 | Y20: 0 | Z20: 0.3518423 | AA20: 0 | AB20: 0 | AC20: 0 | AD20: 0.15902003 | AE20: 0.030253553 | AF20: 0.17393548 | AG20: 1
D21: META | E21: 0.024124434 | F21: 0.058405784 | G21: 0.052010369 | H21: 0.038753877 | I21: 0.022574916 | J21: 0.16994401 | K21: 0.047091705 | L21: 0.096754478 | M21: 0.040148541 | N21: 0.052229815 | Q21: 0.19797228 | S21: Eff PF with mean = 20% | T21: 0.10392032 | U21: 0 | V21: 0.11091757 | W21: 0.18165969 | X21: 0.29895298 | Y21: 0 | Z21: 0.29671502 | AA21: 0 | AB21: 0.0078344181 | AC21: 0 | AD21: 0.2 | AE21: 0.032921479 | AF21: 0.18144277 | AG21: 1
D22: MSFT | E22: 0.027718186 | F22: 0.04238045 | G22: 0.042856643 | H22: 0.033326094 | I22: 0.014751656 | J22: 0.047091705 | K22: 0.046004026 | L22: 0.074564916 | M22: 0.046483274 | N22: 0.053205891 | Q22: 0.18313395 | S22: Eff PF with mean = 25% | T22: 0.08621017 | U22: 0 | V22: 0.23105987 | W22: 0.17502388 | X22: 0.24031627 | Y22: 0 | Z22: 0.19285805 | AA22: 0 | AB22: 0.07453175 | AC22: 0 | AD22: 0.25 | AE22: 0.039213997 | AF22: 0.19802524 | AG22: 1
D23: NVDA | E23: 0.063054372 | F23: 0.10089767 | G23: 0.09185041 | H23: 0.070510063 | I23: 0.028225724 | J23: 0.096754478 | K23: 0.074564916 | L23: 0.2351543 | M23: 0.090757103 | N23: 0.11505569 | Q23: 0.51174349 | S23: Eff PF with mean = 30% | T23: 0.068500034 | U23: 0 | V23: 0.35120217 | W23: 0.16838798 | X23: 0.18167952 | Y23: 0 | Z23: 0.089001232 | AA23: 0 | AB23: 0.14122905 | AC23: 0 | AD23: 0.3 | AE23: 0.04849681 | AF23: 0.22021991 | AG23: 1
D24: ORCL | E24: 0.035784841 | F24: 0.046696533 | G24: 0.051311451 | H24: 0.03806205 | I24: 0.02883776 | J24: 0.040148541 | K24: 0.046483274 | L24: 0.090757103 | M24: 0.11751992 | N24: 0.060978647 | Q24: 0.34043308 | S24: Eff PF with mean = 35% | T24: 0.039304135 | U24: 0 | V24: 0.45259896 | W24: 0.15448694 | X24: 0.13476724 | Y24: 0 | Z24: 0 | AA24: 0.027777052 | AB24: 0.19106566 | AC24: 0 | AD24: 0.35 | AE24: 0.060669694 | AF24: 0.24631219 | AG24: 1
D25: TSLA | E25: 0.085253063 | F25: 0.10664435 | G25: 0.083582926 | H25: 0.07412726 | I25: 0.02209394 | J25: 0.052229815 | K25: 0.053205891 | L25: 0.11505569 | M25: 0.060978647 | N25: 0.36666533 | Q25: 0.21600124 | S25: Eff PF with mean = 40% | T25: 0 | U25: 0 | V25: 0.55503809 | W25: 0.10206372 | X25: 0.058381001 | Y25: 0 | Z25: 0 | AA25: 0.062707806 | AB25: 0.22180938 | AC25: 0 | AD25: 0.400001 | AE25: 0.075853785 | AF25: 0.27541566 | AG25: 1
S26: Eff PF with mean = 45% | T26: 0 | U26: 0 | V26: 0.67764469 | W26: 0 | X26: 0 | Y26: 0 | Z26: 0 | AA26: 0.12196086 | AB26: 0.20039445 | AC26: 0 | AD26: 0.45 | AE26: 0.094793416 | AF26: 0.30788539 | AG26: 1
S27: Eff PF with mean = 50% | T27: 0 | U27: 0 | V27: 0.29028817 | W27: 0 | X27: 0 | Y27: 0 | Z27: 0 | AA27: 0.70971183 | AB27: 0 | AC27: 0 | AD27: 0.5 | AE27: 0.16602125 | AF27: 0.40745706 | AG27: 1
S28: Eff PF with mean = 51% | T28: 0 | U28: 0 | V28: 0 | W28: 0 | X28: 0 | Y28: 0 | Z28: 0 | AA28: 1 | AB28: 0 | AC28: 0 | AD28: 0.51174349 | AE28: 0.2351543 | AF28: 0.48492711 | AG28: 1
S29: Risk free rate | AD29: 0.04 | AF29: 0
T31: 0 | U31: 0 | V31: 0.73734317 | W31: 0 | X31: 0 | Y31: 0 | Z31: 0 | AA31: 0.26265683 | AB31: 0 | AC31: 0 | AD31: 0.48191458 | AE31: 0.1145757 | AF31: 0.33849033 | AG31: 1 | AH31: 200 | AI31: 0.36733888
T32: 0 | U32: 0 | V32: 0.68873524 | W32: 0 | X32: 0 | Y32: 0 | Z32: 0 | AA32: 0.13576368 | AB32: 0.17550107 | AC32: 0 | AD32: 0.45381583 | AE32: 0.096632083 | AF32: 0.31085701 | AG32: 1 | AH32: 400 | AI32: 0.26055166
